Workbook
Name _Hlk109387980: #REF!
Name Query_from_MS_Access_Database_1: 'NON TEACHING STAFF'!$J$5:$CG$246
Name Query_from_MS_Access_Database_1: 'TEACHING STAFF'!$G$4:$BP$177

Sheet TEACHING STAFF
B1: UNIVERSITY OF AFRICA, TORU-ORUA.
B2: STAFF PAYROLL FOR THE MONTH OF FEBRUARY, 2026. | CE2: =#REF! -> #REF!
A3: S/N | B3: NAMES OF STAFF | C3: DEPARTMENT | D3: JOB DESCRIPTION | E3: GRADE NAME | F3: BANK NAME | G3: ACCT NO | H3: ANNUAL SALARY | I3: ANNUAL | J3: OLD BASIC | K3: 25/35% increment | L3: minimum wage | M3: NEW BASIC | N3: EXCESS WORK LOAD | O3: FIELD TRIP | P3: RESPONSIBILITY | Q3: Field Trip | R3: MEDICAL | S3: ARREARS | T3: PERCULIAR | U3: PERSONAL ASSISTANT | V3: LEAVE ALLOWANCE | W3: NEWSPAPER ALLOWANCE | Y3: INDUCEMENT | Z3: GENERAL HAZARD | AA3: OTHER ALLOWS/ADDEDUM | AB3: DOMESTIC STAFF ALLOW. | AC3: Shift | AD3: RESPONSIBILITY ALLOW. | AE3: Entertainment | AF3: Responsibility | AG3: Other Addtions | AI3: SALARY ADVACE | AJ3: ANUPA | AK3: UTILITY BILL | AL3: TOP LIFTER LIMITED | AM3: ASUU | AN3: ASUU WELFARE | AO3: FASTGROW | AP3: FLORIS MULTI PURPOSE | AQ3: FBAS WELFARE | AR3: PERSONAL OWING | AS3: FAE DEUCATION | AT3: BELKARI LOANS | AU3: SCHOOL FEES DEDUCTION | AV3: UAT CRESTED POLO | AW3: FMS WELFARE DEDUCTION | AX3: FSS WELFARE DEDUCTION | AY3: UAT FEMALE FORUM | AZ3: ECONOMICS | BA3: UAT CO-OPERATIVE | BB3: FLORESHINE GLOBAL | BC3: UTILITY BILLS | BD3: UAT RENT | BE3: BSETF | BF3: SCHOOL /HOSTELFEES | BG3: EXTRA DEPENDENT BHIS | BH3: BHIS | BI3: NHF | BJ3: BMUWMPCS | BK3: P.A.Y.E. | BL3: GROSS PAYBEFORE | BM3: TOT DEDUCT | BN3: Sal. advance | BO3: PERCENTAGES | BP3: NET PAY | BQ3: Gosss Earnings | BR3: Personal Allowance | BS3: NHF | BT3: Total Non-Taxable Income | BU3: Total Taxable Income | BV3: Minimum tax | BW3: 1st 300K @ 7% | BX3: next 300k @ 11% | BY3: next 500k @ 15% | BZ3: next 500k @ 19% | CA3: next 1.6m @ 21% | CB3: above 3.2m @ 24% | CC3: Total PAYE | CD3: Min Tax | CE3: Total PAYE Tax | CF3: Monthly PAYE Tax | CG3: 20% Rebate | CH3: ETR | CI3: Current deductions | CJ3: Underpayment (monthly) | CK3: Underpayment (annual) | CN3: REMARK
A4: 1 | B4: ADEMOLA AYODEJI JOLAYEMI | C4: ENGLISH AND LITERARY STUDIES | D4: DEAN, POST-GRADUATE SCHOOL | E4: CONUSS 7/10 | F4: FIRST | G4: 2017212564 | H4: =M4*12 -> 9356702.4 | I4: =M4*12 -> 9356702.4 | J4: 555352 | K4: 194373.2 | L4: 30000 | M4: =SUM(J4:L4) -> 779725.2 | N4: =M4*0.35/3 -> 90967.94 | O4: 8333.33 | P4: =41667 -> 41667 | R4: 2500 | U4: 250000 | Z4: 2500 | AM4: =M4*0.02 -> 15594.504 | AN4: 500 | AP4: 100000 | AS4: 1000 | BA4: 456250 | BC4: 12500 | BD4: 25000 | BE4: 3500 | BF4: 3500 | BH4: =BL4*0.02 -> 23513.869 | BK4: 204399.81 | BL4: =M4+N4+O4+P4+R4+S4+T4+U4+V4+W4+Y4+Z4+AA4+AB4 -> 1175693.5 | BM4: 845758.18 | BP4: =BL4-BM4 -> 329935.29 | BQ4: =BL4*12 -> 14108322 | BR4: =200000+(0.2*BQ4) -> 3021664.3 | BS4: =BI4*12 -> 0 | BT4: =SUM(BR4:BS4) -> 3021664.3 | BU4: =+BQ4-BT4 -> 11086657 | BW4: =IF((BU4>0),(IF((BU4>300000),(300000*7%),(BU4*7%))),(BQ4*1%)) -> 21000 | BX4: =IF((BU4-300000)>0,(IF((BU4>600000),(300000*11%),((BU4-300000)*11%))),("")) -> 33000 | BY4: =IF(((BU4-600000)>0),(IF((BU4>1100000),(500000*15%),((BU4-600000)*15%))),("")) -> 75000 | BZ4: =IF(((BU4-(1100000))>0),(IF((BU4>(1600000)),((500000)*19%),((BU4-(1100000))*19%))),("")) -> 95000 | CA4: =IF(((BU4-(1600000))>0),(IF((BU4>(3200000)),((1600000)*21%),((BU4-(1600000))*21%))),("")) -> 336000 | CB4: =IF(((BU4-(3200000))>0),(IF((BU4>(3200000)),((BU4-(3200000))*24%),(0))),("")) -> 1892797.8 | CC4: =SUM(BW4:CB4) -> 2452797.8 | CD4: =1%*BQ4 -> 141083.22 | CE4: =MAX(CC4:CD4) -> 2452797.8 | CF4: =+CE4/12 -> 204399.81
A5: 2 | B5: SIKOKI FRANCIS DAVID | C5: BIOLOGICAL SCIENCE | D5: DEAN BASIC AND APPLIED SCIENCE (CONTRACT PROFESSOR) | E5: CONUSS 7/10 | F5: ACCESS | G5: 0055002341 | H5: =M5*12 -> 9356702.4 | I5: =M5*12 -> 9356702.4 | J5: 555352 | K5: 194373.2 | L5: 30000 | M5: =SUM(J5:L5) -> 779725.2 | P5: =41667 -> 41667 | R5: 2500 | Z5: 2500 | AM5: =M5*0.02 -> 15594.504 | AN5: 500 | AQ5: 1000 | BC5: 12500 | BD5: 25000 | BE5: 3500 | BF5: 3500 | BH5: =BL5*0.02 -> 16527.844 | BK5: 137333.97 | BL5: =M5+N5+O5+P5+R5+S5+T5+U5+V5+W5+Y5+Z5+AA5 -> 826392.2 | BM5: 215456.32 | BP5: =BL5-BM5 -> 610935.88 | BQ5: =BL5*12 -> 9916706.4 | BR5: =200000+(0.2*BQ5) -> 2183341.3 | BS5: =BI5*12 -> 0 | BT5: =SUM(BR5:BS5) -> 2183341.3 | BU5: =+BQ5-BT5 -> 7733365.1 | BW5: =IF((BU5>0),(IF((BU5>300000),(300000*7%),(BU5*7%))),(BQ5*1%)) -> 21000 | BX5: =IF((BU5-300000)>0,(IF((BU5>600000),(300000*11%),((BU5-300000)*11%))),("")) -> 33000 | BY5: =IF(((BU5-600000)>0),(IF((BU5>1100000),(500000*15%),((BU5-600000)*15%))),("")) -> 75000 | BZ5: =IF(((BU5-(1100000))>0),(IF((BU5>(1600000)),((500000)*19%),((BU5-(1100000))*19%))),("")) -> 95000 | CA5: =IF(((BU5-(1600000))>0),(IF((BU5>(3200000)),((1600000)*21%),((BU5-(1600000))*21%))),("")) -> 336000 | CB5: =IF(((BU5-(3200000))>0),(IF((BU5>(3200000)),((BU5-(3200000))*24%),(0))),("")) -> 1088007.6 | CC5: =SUM(BW5:CB5) -> 1648007.6 | CD5: =1%*BQ5 -> 99167.064 | CE5: =MAX(CC5:CD5) -> 1648007.6 | CF5: =+CE5/12 -> 137333.97
A6: 3 | B6: ABUMERE OAMEN ERONMOSELE | C6: ='[1]TEACHING STAFF'!$D$6 -> PHYSICS | D6: CONTRACT APPOINTMENT | E6: CONUSS 7/10 | F6: ECOBANK | G6: 0072045836 | J6: 555352 | K6: 194373.2 | L6: 30000 | M6: =SUM(J6:L6) -> 779725.2 | P6: 20833.33 | R6: 2500 | Z6: 2500 | AM6: =M6*0.02 -> 15594.504 | AN6: 500 | AQ6: 1000 | BC6: 4166.67 | BD6: ='[1]TEACHING STAFF'!$AS$6 -> 8333.33 | BE6: 3500 | BF6: 3500 | BH6: =BL6*0.02 -> 16111.171 | BK6: 133333.9 | BL6: =M6+N6+O6+P6+R6+S6+T6+U6+V6+W6+Y6+Z6+AA6 -> 805558.53 | BM6: =BK6+BH6+BE6+BD6+BC6+AQ6+AN6+AM6 -> 182539.57 | BP6: =BL6-BM6 -> 623018.96
A7: 4 | B7: DONBEBE WANKASI | C7: CHEMICAL SCIENCES | D7: ADJUNCT PROFESSOR | E7: CONUSS 7/3 | F7: ACCESS | G7: 0026574605 | H7: =M7*12 -> 3843072.5 | J7: 319245.33 | K7: 45673.005 | L7: 15000 | M7: 320256.04 | R7: 2500 | Z7: 2500 | AC7: 0 | AM7: =M7*0.02 -> 6405.1208 | AN7: 500 | AQ7: 1000 | BE7: 1750 | BH7: =BL7*0.02 -> 6505.1208 | BK7: 41809.681 | BL7: =M7+N7+O7+P7+R7+S7+T7+U7+V7+W7+Y7+Z7+AA7 -> 325256.04 | BM7: =AI7+AJ7+AK7+AL7+AM7+AN7+AP7++AQ7+AR7+AS7+AT7+AU7+AV7+AW7+AX7+AY7+AZ7+BA7+BB7+BC7+BD7+BE7+BG7+BH7+BK7 -> 57969.923 | BP7: =BL7-BM7 -> 267286.12 | BQ7: =BL7*12 -> 3903072.5 | BR7: =200000+(0.2*BQ7) -> 980614.5 | BS7: =BI7*12 -> 0 | BT7: =SUM(BR7:BS7) -> 980614.5 | BU7: =+BQ7-BT7 -> 2922458 | BW7: =IF((BU7>0),(IF((BU7>300000),(300000*7%),(BU7*7%))),(BQ7*1%)) -> 21000 | BX7: =IF((BU7-300000)>0,(IF((BU7>600000),(300000*11%),((BU7-300000)*11%))),("")) -> 33000 | BY7: =IF(((BU7-600000)>0),(IF((BU7>1100000),(500000*15%),((BU7-600000)*15%))),("")) -> 75000 | BZ7: =IF(((BU7-(1100000))>0),(IF((BU7>(1600000)),((500000)*19%),((BU7-(1100000))*19%))),("")) -> 95000 | CA7: =IF(((BU7-(1600000))>0),(IF((BU7>(3200000)),((1600000)*21%),((BU7-(1600000))*21%))),("")) -> 277716.18 | CB7: =IF(((BU7-(3200000))>0),(IF((BU7>(3200000)),((BU7-(3200000))*24%),(0))),("")) | CC7: =SUM(BW7:CB7) -> 501716.18 | CD7: =1%*BQ7 -> 39030.725 | CE7: =MAX(CC7:CD7) -> 501716.18 | CF7: =BK7 -> 41809.681 | CN7: ADJUNCT EXPIRES WITH THE 2025/2026 ACADEMIC SESSION
A8: 5 | B8: CHINYERE P. ONONUGBO | C8: PHYSICS | D8: ADJUNCT PROFESSOR | E8: CONUAS 7/3 | F8: UBA | G8: 2088596893 | M8: =640512.08/2 -> 320256.04 | R8: 2500 | Z8: 2500 | AC8: 0 | AM8: =M8*0.02 -> 6405.1208 | AN8: 500 | AQ8: 1000 | BE8: 1750 | BH8: =BL8*0.02 -> 6505.1208 | BK8: 41809.681 | BL8: =M8+N8+O8+P8+R8+S8+T8+U8+V8+W8+Y8+Z8+AA8 -> 325256.04 | BM8: =AI8+AJ8+AK8+AL8+AM8+AN8+AP8++AQ8+AR8+AS8+AT8+AU8+AV8+AW8+AX8+AY8+AZ8+BA8+BB8+BC8+BD8+BE8+BG8+BH8+BK8 -> 57969.923 | BP8: =BL8-BM8 -> 267286.12 | CN8: ADJUNCT EXPIRES WITH THE 2025/2026 ACADEMIC SESSION
A9: 6 | B9: DANIEL I. OLORUNFEMI | C9: BIOLOGICAL SCIENCE | D9: ADJUNCT PROFESSOR | E9: CONUAS 7/9 | F9: ACCESS | G9: 0030621811 | H9: =M9*12 -> 4559020 | J9: 319245.33 | K9: 45673.005 | L9: 15000 | M9: =SUM(J9:L9) -> 379918.34 | R9: 2500 | Z9: 2500 | AC9: 0 | AM9: =M9*0.02 -> 7598.3667 | AN9: 500 | AQ9: 1000 | BE9: 1750 | BH9: =BL9*0.02 -> 7698.3667 | BK9: 52570.987 | BL9: =M9+N9+O9+P9+R9+S9+T9+U9+V9+W9+Y9+Z9+AA9 -> 384918.34 | BM9: =AI9+AJ9+AK9+AL9+AM9+AN9+AP9++AQ9+AR9+AS9+AT9+AU9+AV9+AW9+AX9+AY9+AZ9+BA9+BB9+BC9+BD9+BE9+BG9+BH9+BK9 -> 71117.72 | BP9: =BL9-BM9 -> 313800.61 | CN9: ADJUNCT EXPIRES WITH THE 2025/2026 ACADEMIC SESSION
A10: 7 | B10: OKOROBIA MARK ATEI | C10: HISTORY AND INTERNATIONAL STUDIES | D10: ADJUNCT PROFESSOR | E10: CONUSS 7/10 | F10: UBA | G10: 1006415522 | J10: 277675.58 | K10: 97186.454 | L10: 15000 | M10: =SUM(J10:L10) -> 389862.04 | R10: 2500 | Z10: 2500 | AC10: 0 | AM10: =M10*0.02 -> 7797.2407 | AN10: 500 | AO10: 0 | AS10: 1000 | BE10: 1750 | BH10: =BL10*0.02 -> 7897.2407 | BK10: 54480.178 | BL10: =M10+N10+O10+P10+R10+S10+T10+U10+V10+W10+Y10+Z10+AA10 -> 394862.04 | BM10: =AI10+AJ10+AK10+AL10+AM10+AN10+AP10++AQ10+AR10+AS10+AT10+AU10+AV10+AW10+AX10+AY10+AZ10+BA10+BB10+BC10+BD10+BE10+BG10+BH10+BK10 -> 73424.659 | BP10: =BL10-BM10 -> 321437.38 | BQ10: =BM10-BN10 -> 73424.659 | CN10: ADJUNCT EXPIRES WITH THE 2025/2026 ACADEMIC SESSION
A11: 8 | B11: EBISEITEI PRECIOUS | C11: BIOLOGICAL SCIENCE | D11: SENIOR LECTURER | E11: CONUSSS 5/3 | F11: STANBIC IBTC | G11: 0035529328 | H11: 2425322 | I11: 2688069 | J11: 224005.75 | K11: 56001.438 | L11: 30000 | M11: 413255.25 | N11: =M11*0.35/3 -> 48213.113 | O11: 5000 | P11: 41667 | R11: 2500 | Z11: 2500 | AM11: =M11*0.02 -> 8265.105 | AN11: 500 | AQ11: 1000 | AV11: 5000 | BE11: 1500 | BH11: =BL11*0.02 -> 10262.707 | BK11: 77188.66 | BL11: =M11+N11+O11+P11+R11+S11+T11+U11+V11+W11+Y11+Z11+AA11 -> 513135.36 | BM11: =AI11+AJ11+AK11+AL11+AM11+AN11+AP11++AQ11+AR11+AS11+AT11+AU11+AV11+AW11+AX11+AY11+AZ11+BA11+BB11+BC11+BD11+BE11+BG11+BH11+BK11 -> 103716.47 | BP11: =BL11-BM11 -> 409418.89 | BQ11: =BL11*12 -> 6157624.3 | BR11: =200000+(0.2*BQ11) -> 1431524.9 | BS11: =BI11*12 -> 0 | BT11: =SUM(BR11:BS11) -> 1431524.9 | BU11: =+BQ11-BT11 -> 4726099.5 | BW11: =IF((BU11>0),(IF((BU11>300000),(300000*7%),(BU11*7%))),(BQ11*1%)) -> 21000 | BX11: =IF((BU11-300000)>0,(IF((BU11>600000),(300000*11%),((BU11-300000)*11%))),("")) -> 33000 | BY11: =IF(((BU11-600000)>0),(IF((BU11>1100000),(500000*15%),((BU11-600000)*15%))),("")) -> 75000 | BZ11: =IF(((BU11-(1100000))>0),(IF((BU11>(1600000)),((500000)*19%),((BU11-(1100000))*19%))),("")) -> 95000 | CA11: =IF(((BU11-(1600000))>0),(IF((BU11>(3200000)),((1600000)*21%),((BU11-(1600000))*21%))),("")) -> 336000 | CB11: =IF(((BU11-(3200000))>0),(IF((BU11>(3200000)),((BU11-(3200000))*24%),(0))),("")) -> 366263.88 | CC11: =SUM(BW11:CB11) -> 926263.88 | CD11: =1%*BQ11 -> 61576.243 | CE11: =MAX(CC11:CD11) -> 926263.88 | CF11: =+CE11/12 -> 77188.656
A12: 9 | B12: ZIAKEDE SOLOMON KOROYE | C12: PHYSICS | D12: LECTURER II | E12: CONUASS 3/6 | F12: GTB | G12: 0237212657 | H12: 2048214 | I12: 2144788 | J12: 178732.33 | K12: 44683.083 | L12: 30000 | M12: 259114.17 | N12: =M12*0.35/3 -> 30229.986 | O12: 5000 | R12: 2500 | Z12: 2500 | AM12: =M12*0.02 -> 5182.2834 | AN12: 500 | AQ12: 1000 | BA12: 5000 | BE12: 1000 | BH12: =BL12*0.02 -> 5986.8831 | BK12: 37456.48 | BL12: =M12+N12+O12+P12+R12+S12+T12+U12+V12+W12+Y12+Z12+AA12 -> 299344.16 | BM12: =AI12+AJ12+AK12+AL12+AM12+AN12+AP12++AQ12+AR12+AS12+AT12+AU12+AV12+AW12+AX12+AY12+AZ12+BA12+BB12+BC12+BD12+BE12+BG12+BH12+BK12 -> 56125.647 | BP12: =BL12-BM12 -> 243218.51 | BQ12: =BL12*12 -> 3592129.9 | BR12: =200000+(0.2*BQ12) -> 918425.98 | BS12: =BI12*12 -> 0 | BT12: =SUM(BR12:BS12) -> 918425.98 | BU12: =+BQ12-BT12 -> 2673703.9 | BW12: =IF((BU12>0),(IF((BU12>300000),(300000*7%),(BU12*7%))),(BQ12*1%)) -> 21000 | BX12: =IF((BU12-300000)>0,(IF((BU12>600000),(300000*11%),((BU12-300000)*11%))),("")) -> 33000 | BY12: =IF(((BU12-600000)>0),(IF((BU12>1100000),(500000*15%),((BU12-600000)*15%))),("")) -> 75000 | BZ12: =IF(((BU12-(1100000))>0),(IF((BU12>(1600000)),((500000)*19%),((BU12-(1100000))*19%))),("")) -> 95000 | CA12: =IF(((BU12-(1600000))>0),(IF((BU12>(3200000)),((1600000)*21%),((BU12-(1600000))*21%))),("")) -> 225477.82 | CB12: =IF(((BU12-(3200000))>0),(IF((BU12>(3200000)),((BU12-(3200000))*24%),(0))),("")) | CC12: =SUM(BW12:CB12) -> 449477.82 | CD12: =1%*BQ12 -> 35921.299 | CE12: =MAX(CC12:CD12) -> 449477.82 | CF12: =+CE12/12 -> 37456.485
A13: 10 | B13: DEINGIMO KEME | C13: BIOLOGICAL SCIENCE | D13: LECTURER I | E13: CONUASS 4/3 | F13: UBA | G13: 2067246166 | H13: 2308911 | I13: 2048214 | J13: 192409.25 | K13: 48102.312 | L13: 30000 | M13: 319130.33 | N13: =M13*0.35/3 -> 37231.872 | O13: 5000 | R13: 2500 | Z13: 2500 | AM13: =M13*0.02 -> 6382.6066 | AN13: 500 | AP13: 21000 | AQ13: 1000 | BA13: 0 | BE13: 1500 | BH13: =BL13*0.02 -> 7327.244 | BK13: 49008.21 | BL13: =M13+N13+O13+P13+R13+S13+T13+U13+V13+W13+Y13+Z13+AA13 -> 366362.2 | BM13: =AI13+AJ13+AK13+AL13+AM13+AN13+AP13++AQ13+AR13+AS13+AT13+AU13+AV13+AW13+AX13+AY13+AZ13+BA13+BB13+BC13+BD13+BE13+BG13+BH13+BK13 -> 86718.061 | BP13: =BL13-BM13 -> 279644.14 | BQ13: =BL13*12 -> 4396346.4 | BR13: =200000+(0.2*BQ13) -> 1079269.3 | BS13: =BI13*12 -> 0 | BT13: =SUM(BR13:BS13) -> 1079269.3 | BU13: =+BQ13-BT13 -> 3317077.1 | BW13: =IF((BU13>0),(IF((BU13>300000),(300000*7%),(BU13*7%))),(BQ13*1%)) -> 21000 | BX13: =IF((BU13-300000)>0,(IF((BU13>600000),(300000*11%),((BU13-300000)*11%))),("")) -> 33000 | BY13: =IF(((BU13-600000)>0),(IF((BU13>1100000),(500000*15%),((BU13-600000)*15%))),("")) -> 75000 | BZ13: =IF(((BU13-(1100000))>0),(IF((BU13>(1600000)),((500000)*19%),((BU13-(1100000))*19%))),("")) -> 95000 | CA13: =IF(((BU13-(1600000))>0),(IF((BU13>(3200000)),((1600000)*21%),((BU13-(1600000))*21%))),("")) -> 336000 | CB13: =IF(((BU13-(3200000))>0),(IF((BU13>(3200000)),((BU13-(3200000))*24%),(0))),("")) -> 28098.513 | CC13: =SUM(BW13:CB13) -> 588098.51 | CD13: =1%*BQ13 -> 43963.464 | CE13: =MAX(CC13:CD13) -> 588098.51 | CF13: =+CE13/12 -> 49008.209
A14: 11 | B14: TARIEBIBO ENAI GEDE | C14: MATHEMATICS AND COMPUTER SCIENCE | D14: LECTURER I | E14: CONUASS 4/6 | F14: STERLING | G14: 0077840928 | H14: 2688069 | I14: 2775651 | J14: 231304.25 | K14: 57826.062 | L14: 30000 | M14: 328253.42 | N14: =M14*0.35/3 -> 38296.232 | O14: 5000 | R14: 2500 | Z14: 2500 | AM14: =M14*0.02 -> 6565.0684 | AN14: 500 | AQ14: 1000 | BA14: 19333.33 | BE14: 1500 | BH14: =BL14*0.02 -> 7530.993 | BK14: 50964.2 | BL14: =M14+N14+O14+P14+R14+S14+T14+U14+V14+W14+Y14+Z14+AA14 -> 376549.65 | BM14: =AI14+AJ14+AK14+AL14+AM14+AN14+AP14++AQ14+AR14+AS14+AT14+AU14+AV14+AW14+AX14+AY14+AZ14+BA14+BB14+BC14+BD14+BE14+BG14+BH14+BK14 -> 87393.591 | BP14: =BL14-BM14 -> 289156.06 | BQ14: =BL14*12 -> 4518595.8 | BR14: =200000+(0.2*BQ14) -> 1103719.2 | BS14: =BI14*12 -> 0 | BT14: =SUM(BR14:BS14) -> 1103719.2 | BU14: =+BQ14-BT14 -> 3414876.7 | BW14: =IF((BU14>0),(IF((BU14>300000),(300000*7%),(BU14*7%))),(BQ14*1%)) -> 21000 | BX14: =IF((BU14-300000)>0,(IF((BU14>600000),(300000*11%),((BU14-300000)*11%))),("")) -> 33000 | BY14: =IF(((BU14-600000)>0),(IF((BU14>1100000),(500000*15%),((BU14-600000)*15%))),("")) -> 75000 | BZ14: =IF(((BU14-(1100000))>0),(IF((BU14>(1600000)),((500000)*19%),((BU14-(1100000))*19%))),("")) -> 95000 | CA14: =IF(((BU14-(1600000))>0),(IF((BU14>(3200000)),((1600000)*21%),((BU14-(1600000))*21%))),("")) -> 336000 | CB14: =IF(((BU14-(3200000))>0),(IF((BU14>(3200000)),((BU14-(3200000))*24%),(0))),("")) -> 51570.399 | CC14: =SUM(BW14:CB14) -> 611570.4 | CD14: =1%*BQ14 -> 45185.958 | CE14: =MAX(CC14:CD14) -> 611570.4 | CF14: =+CE14/12 -> 50964.2
A15: 12 | B15: LAWAL BABATUNDE YUSUF | C15: PHYSICS | D15: ASSOCIATE PROFESSOR | E15: CONUAS 6/1 | F15: STERLING | G15: 0071870439 | H15: 3588849 | I15: 3679250 | J15: 306604.17 | K15: 76651.042 | L15: 30000 | M15: 464981 | N15: =M15*0.35/3 -> 54247.783 | O15: 5000 | R15: 2500 | Z15: 2500 | AM15: =M15*0.02 -> 9299.62 | AN15: 500 | AP15: 101667 | AQ15: 1000 | BA15: 85000 | BC15: 7500 | BD15: 15000 | BE15: 2000 | BH15: =BL15*0.02 -> 10584.576 | BK15: 80278.59 | BL15: =M15+N15+O15+P15+R15+S15+T15+U15+V15+W15+Y15+Z15+AA15 -> 529228.78 | BM15: =AI15+AJ15+AK15+AL15+AM15+AN15+AP15++AQ15+AR15+AS15+AT15+AU15+AV15+AW15+AX15+AY15+AZ15+BA15+BB15+BC15+BD15+BE15+BG15+BH15+BK15 -> 312829.79 | BP15: =BL15-BM15 -> 216399 | BQ15: =BL15*12 -> 6350745.4 | BR15: =200000+(0.2*BQ15) -> 1470149.1 | BS15: =BI15*12 -> 0 | BT15: =SUM(BR15:BS15) -> 1470149.1 | BU15: =+BQ15-BT15 -> 4880596.3 | BW15: =IF((BU15>0),(IF((BU15>300000),(300000*7%),(BU15*7%))),(BQ15*1%)) -> 21000 | BX15: =IF((BU15-300000)>0,(IF((BU15>600000),(300000*11%),((BU15-300000)*11%))),("")) -> 33000 | BY15: =IF(((BU15-600000)>0),(IF((BU15>1100000),(500000*15%),((BU15-600000)*15%))),("")) -> 75000 | BZ15: =IF(((BU15-(1100000))>0),(IF((BU15>(1600000)),((500000)*19%),((BU15-(1100000))*19%))),("")) -> 95000 | CA15: =IF(((BU15-(1600000))>0),(IF((BU15>(3200000)),((1600000)*21%),((BU15-(1600000))*21%))),("")) -> 336000 | CB15: =IF(((BU15-(3200000))>0),(IF((BU15>(3200000)),((BU15-(3200000))*24%),(0))),("")) -> 403343.12 | CC15: =SUM(BW15:CB15) -> 963343.12 | CD15: =1%*BQ15 -> 63507.454 | CE15: =MAX(CC15:CD15) -> 963343.12 | CF15: =+CE15/12 -> 80278.593
A16: 13 | B16: NEIN GODKNOWS | C16: INDUSTRAL RELATION AND PERSONAL MGT | D16: SENIOR LECTURER | E16: CONUAS 5/9 | F16: UNION | G16: 0029213035 | I16: 4307259 | J16: 358938.25 | K16: 89734.562 | L16: 30000 | M16: 491756.42 | N16: =M16*0.35/3 -> 57371.582 | O16: 5000 | P16: =P17 -> 20833.33 | R16: 2500 | Z16: 2500 | AM16: =M16*0.02 -> 9835.1284 | AN16: 500 | AV16: 5000 | AW16: 1000 | AX16: 1000 | BA16: 0 | BE16: 2000 | BH16: =BL16*0.02 -> 11599.227 | BK16: 90019.24 | BL16: =M16+N16+O16+P16+R16+S16+T16+U16+V16+W16+Y16+Z16+AA16 -> 579961.33 | BM16: =AI16+AJ16+AK16+AL16+AM16+AN16+AP16++AQ16+AR16+AS16+AT16+AU16+AV16+AW16+AX16+AY16+AZ16+BA16+BB16+BC16+BD16+BE16+BG16+BH16+BK16 -> 120953.6 | BP16: =BL16-BM16 -> 459007.74 | BQ16: =BL16*12 -> 6959536 | BR16: =200000+(0.2*BQ16) -> 1591907.2 | BS16: =BI16*12 -> 0 | BT16: =SUM(BR16:BS16) -> 1591907.2 | BU16: =+BQ16-BT16 -> 5367628.8 | BW16: =IF((BU16>0),(IF((BU16>300000),(300000*7%),(BU16*7%))),(BQ16*1%)) -> 21000 | BX16: =IF((BU16-300000)>0,(IF((BU16>600000),(300000*11%),((BU16-300000)*11%))),("")) -> 33000 | BY16: =IF(((BU16-600000)>0),(IF((BU16>1100000),(500000*15%),((BU16-600000)*15%))),("")) -> 75000 | BZ16: =IF(((BU16-(1100000))>0),(IF((BU16>(1600000)),((500000)*19%),((BU16-(1100000))*19%))),("")) -> 95000 | CA16: =IF(((BU16-(1600000))>0),(IF((BU16>(3200000)),((1600000)*21%),((BU16-(1600000))*21%))),("")) -> 336000 | CB16: =IF(((BU16-(3200000))>0),(IF((BU16>(3200000)),((BU16-(3200000))*24%),(0))),("")) -> 520230.91 | CC16: =SUM(BW16:CB16) -> 1080230.9 | CD16: =1%*BQ16 -> 69595.36 | CE16: =MAX(CC16:CD16) -> 1080230.9 | CF16: =+CE16/12 -> 90019.242
A17: 14 | B17: ECHETA O SYDNEY | C17: HOTEL MANAGEMENT AND TOURISM | D17: SENIOR LECTURER | E17: CONUASS 5/4 | F17: FIRST | G17: 3013002388 | H17: 3588849 | I17: 3679250 | J17: 306604.17 | K17: 76651.042 | L17: 30000 | M17: 426338.75 | N17: =M17*0.35/3 -> 49739.521 | O17: 5000 | P17: 20833.33 | R17: 2500 | Z17: 2500 | AM17: =M17*0.02 -> 8526.775 | AN17: 500 | AW17: 1000 | BA17: 0 | BC17: 3750 | BD17: 7500 | BE17: 2000 | BH17: =BL17*0.02 -> 10138.232 | BK17: 75993.694 | BL17: =M17+N17+O17+P17+R17+S17+T17+U17+V17+W17+Y17+Z17+AA17 -> 506911.6 | BM17: =AI17+AJ17+AK17+AL17+AM17+AN17+AP17++AQ17+AR17+AS17+AT17+AU17+AV17+AW17+AX17+AY17+AZ17+BA17+BB17+BC17+BD17+BE17+BG17+BH17+BK17 -> 109408.7 | BP17: =BL17-BM17 -> 397502.9 | CF17: =+CE17/12 -> 0
A18: 15 | B18: OGBUTA ANTHONY ANWULI | C18: CHEMICAL SCIENCES | D18: LECTURER I | E18: CONUAS 4/6 | F18: FIRST | G18: 3041696126 | H18: 2688069 | I18: 2775651 | J18: 231304.25 | K18: 57826.062 | L18: 30000 | M18: 328253.42 | N18: =M18*0.35/3 -> 38296.232 | O18: 5000 | R18: 2500 | Z18: 2500 | AM18: =M18*0.02 -> 6565.0684 | AN18: 500 | AQ18: 1000 | BA18: 10000 | BC18: 5000 | BD18: 10000 | BE18: 1500 | BF18: 2000 | BH18: =BL18*0.02 -> 7530.993 | BK18: 50964.2 | BL18: =M18+N18+O18+P18+R18+S18+T18+U18+V18+W18+Y18+Z18+AA18 -> 376549.65 | BM18: =BK18+BH18+BE18+BD18+BC18+BA18+AQ18+AN18+AM18 -> 93060.261 | BP18: =BL18-BM18 -> 283489.39 | BQ18: =BL18*12 -> 4518595.8 | BR18: =200000+(0.2*BQ18) -> 1103719.2 | BS18: =BI18*12 -> 0 | BT18: =SUM(BR18:BS18) -> 1103719.2 | BU18: =+BQ18-BT18 -> 3414876.7 | BW18: =IF((BU18>0),(IF((BU18>300000),(300000*7%),(BU18*7%))),(BQ18*1%)) -> 21000 | BX18: =IF((BU18-300000)>0,(IF((BU18>600000),(300000*11%),((BU18-300000)*11%))),("")) -> 33000 | BY18: =IF(((BU18-600000)>0),(IF((BU18>1100000),(500000*15%),((BU18-600000)*15%))),("")) -> 75000 | BZ18: =IF(((BU18-(1100000))>0),(IF((BU18>(1600000)),((500000)*19%),((BU18-(1100000))*19%))),("")) -> 95000 | CA18: =IF(((BU18-(1600000))>0),(IF((BU18>(3200000)),((1600000)*21%),((BU18-(1600000))*21%))),("")) -> 336000 | CB18: =IF(((BU18-(3200000))>0),(IF((BU18>(3200000)),((BU18-(3200000))*24%),(0))),("")) -> 51570.399 | CC18: =SUM(BW18:CB18) -> 611570.4 | CD18: =1%*BQ18 -> 45185.958 | CE18: =MAX(CC18:CD18) -> 611570.4 | CF18: =+CE18/12 -> 50964.2
A19: 16 | B19: WAIDOR KEITH TAMARAEBI | C19: MATHEMATICS AND COMPUTER SCIENCE | D19: LECTURER I | E19: CONUASS 4/8 | F19: WEMA | G19: 0227351994 | H19: 2863233 | I19: 2950816 | J19: 245901.33 | K19: 61475.333 | L19: 30000 | M19: 346499.83 | N19: =M19*0.35/3 -> 40424.98 | O19: 5000 | R19: 2500 | Z19: 2500 | AM19: =M19*0.02 -> 6929.9966 | AN19: 500 | AQ19: 1000 | BA19: 0 | BC19: 7500 | BD19: 15000 | BE19: 1500 | BH19: =BL19*0.02 -> 7938.4962 | BK19: 54876.23 | BL19: =M19+N19+O19+P19+R19+S19+T19+U19+V19+W19+Y19+Z19+AA19 -> 396924.81 | BM19: =AI19+AJ19+AK19+AL19+AM19+AN19+AP19++AQ19+AR19+AS19+AT19+AU19+AV19+AW19+AX19+AY19+AZ19+BA19+BB19+BC19+BD19+BE19+BG19+BH19+BK19 -> 95244.723 | BP19: =BL19-BM19 -> 301680.09 | BQ19: =BL19*12 -> 4763097.7 | BR19: =200000+(0.2*BQ19) -> 1152619.5 | BS19: =BI19*12 -> 0 | BT19: =SUM(BR19:BS19) -> 1152619.5 | BU19: =+BQ19-BT19 -> 3610478.2 | BW19: =IF((BU19>0),(IF((BU19>300000),(300000*7%),(BU19*7%))),(BQ19*1%)) -> 21000 | BX19: =IF((BU19-300000)>0,(IF((BU19>600000),(300000*11%),((BU19-300000)*11%))),("")) -> 33000 | BY19: =IF(((BU19-600000)>0),(IF((BU19>1100000),(500000*15%),((BU19-600000)*15%))),("")) -> 75000 | BZ19: =IF(((BU19-(1100000))>0),(IF((BU19>(1600000)),((500000)*19%),((BU19-(1100000))*19%))),("")) -> 95000 | CA19: =IF(((BU19-(1600000))>0),(IF((BU19>(3200000)),((1600000)*21%),((BU19-(1600000))*21%))),("")) -> 336000 | CB19: =IF(((BU19-(3200000))>0),(IF((BU19>(3200000)),((BU19-(3200000))*24%),(0))),("")) -> 98514.763 | CC19: =SUM(BW19:CB19) -> 658514.76 | CD19: =1%*BQ19 -> 47630.977 | CE19: =MAX(CC19:CD19) -> 658514.76 | CF19: =+CE19/12 -> 54876.23
A20: 17 | B20: ODUBO CHARITY TAMARAUEBI | C20: ACCOUNTING | D20: LECTURER I | E20: CONUASS 4/4 | F20: STANBIC IBTC | G20: 0019236855 | H20: 2199496 | I20: 2600486 | J20: 216707.17 | K20: 54176.792 | L20: 30000 | M20: 310007.17 | N20: =M20*0.35/3 -> 36167.503 | O20: 5000 | R20: 2500 | Z20: 2500 | AM20: =M20*0.02 -> 6200.1434 | AN20: 500 | AW20: 1000 | AY20: 2000 | BA20: 33339.29 | BE20: 1500 | BH20: =BL20*0.02 -> 7123.4935 | BK20: 47052.2 | BL20: =M20+N20+O20+P20+R20+S20+T20+U20+V20+W20+Y20+Z20+AA20 -> 356174.67 | BM20: =AI20+AJ20+AK20+AL20+AM20+AN20+AP20++AQ20+AR20+AS20+AT20+AU20+AV20+AW20+AX20+AY20+AZ20+BA20+BB20+BC20+BD20+BE20+BG20+BH20+BK20 -> 98715.127 | BP20: =BL20-BM20 -> 257459.55 | BQ20: =BL20*12 -> 4274096.1 | BR20: =200000+(0.2*BQ20) -> 1054819.2 | BS20: =BI20*12 -> 0 | BT20: =SUM(BR20:BS20) -> 1054819.2 | BU20: =+BQ20-BT20 -> 3219276.9 | BW20: =IF((BU20>0),(IF((BU20>300000),(300000*7%),(BU20*7%))),(BQ20*1%)) -> 21000 | BX20: =IF((BU20-300000)>0,(IF((BU20>600000),(300000*11%),((BU20-300000)*11%))),("")) -> 33000 | BY20: =IF(((BU20-600000)>0),(IF((BU20>1100000),(500000*15%),((BU20-600000)*15%))),("")) -> 75000 | BZ20: =IF(((BU20-(1100000))>0),(IF((BU20>(1600000)),((500000)*19%),((BU20-(1100000))*19%))),("")) -> 95000 | CA20: =IF(((BU20-(1600000))>0),(IF((BU20>(3200000)),((1600000)*21%),((BU20-(1600000))*21%))),("")) -> 336000 | CB20: =IF(((BU20-(3200000))>0),(IF((BU20>(3200000)),((BU20-(3200000))*24%),(0))),("")) -> 4626.447 | CC20: =SUM(BW20:CB20) -> 564626.45 | CD20: =1%*BQ20 -> 42740.961 | CE20: =MAX(CC20:CD20) -> 564626.45 | CF20: =+CE20/12 -> 47052.204
A21: 18 | B21: OLADIPO ABOSEDE MOJISOLA | C21: AGRICULTURAL ECONOMICS AND EXTENSION | D21: LECTURER I | E21: CONUASS 4/6 | F21: ZENITH | G21: 2178561969 | H21: =#REF! -> #REF! | I21: 2775651 | J21: 231304.25 | K21: 57826.062 | L21: 30000 | M21: 328253.42 | N21: =M21*0.35/3 -> 38296.232 | O21: 5000 | R21: 2500 | Z21: 2500 | AM21: =M21*0.02 -> 6565.0684 | AN21: 500 | AY21: 2000 | BA21: 0 | BC21: 5000 | BD21: 10000 | BE21: 1500 | BH21: =BL21*0.02 -> 7530.993 | BK21: 50964.2 | BL21: =M21+N21+O21+P21+R21+S21+T21+U21+V21+W21+Y21+Z21+AA21 -> 376549.65 | BM21: =AI21+AJ21+AK21+AL21+AM21+AN21+AP21++AQ21+AR21+AS21+AT21+AU21+AV21+AW21+AX21+AY21+AZ21+BA21+BB21+BC21+BD21+BE21+BG21+BH21+BK21 -> 84060.261 | BP21: =BL21-BM21 -> 292489.39 | BQ21: =BL21*12 -> 4518595.8 | BR21: =200000+(0.2*BQ21) -> 1103719.2 | BS21: =BI21*12 -> 0 | BT21: =SUM(BR21:BS21) -> 1103719.2 | BU21: =+BQ21-BT21 -> 3414876.7 | BW21: =IF((BU21>0),(IF((BU21>300000),(300000*7%),(BU21*7%))),(BQ21*1%)) -> 21000 | BX21: =IF((BU21-300000)>0,(IF((BU21>600000),(300000*11%),((BU21-300000)*11%))),("")) -> 33000 | BY21: =IF(((BU21-600000)>0),(IF((BU21>1100000),(500000*15%),((BU21-600000)*15%))),("")) -> 75000 | BZ21: =IF(((BU21-(1100000))>0),(IF((BU21>(1600000)),((500000)*19%),((BU21-(1100000))*19%))),("")) -> 95000 | CA21: =IF(((BU21-(1600000))>0),(IF((BU21>(3200000)),((1600000)*21%),((BU21-(1600000))*21%))),("")) -> 336000 | CB21: =IF(((BU21-(3200000))>0),(IF((BU21>(3200000)),((BU21-(3200000))*24%),(0))),("")) -> 51570.399 | CC21: =SUM(BW21:CB21) -> 611570.4 | CD21: =1%*BQ21 -> 45185.958 | CE21: =MAX(CC21:CD21) -> 611570.4 | CF21: =+CE21/12 -> 50964.2
A22: 19 | B22: BOLOUPREMO TARILA | C22: BANKING AND FINANCE | D22: ASSOCIATE PROFESSOR | E22: CONUASS 6/1 | F22: STERLING | G22: 0077210321 | H22: 2775651 | I22: 3428047 | J22: 285670.58 | K22: 71417.646 | L22: 30000 | M22: 464981 | N22: =M22*0.35/3 -> 54247.783 | O22: 5000 | P22: 20833.33 | R22: 2500 | Z22: 2500 | AA22: 30000 | AM22: =M22*0.02 -> 9299.62 | AN22: 500 | AP22: 21000 | AW22: 1000 | BA22: 97947 | BE22: 1500 | BG22: =1250*2 -> 2500 | BH22: =BL22*0.02 -> 11601.242 | BK22: 90038.59 | BL22: =M22+N22+O22+P22+R22+S22+T22+U22+V22+W22+Y22+Z22+AA22 -> 580062.11 | BM22: =AI22+AJ22+AK22+AL22+AM22+AN22+AP22++AQ22+AR22+AS22+AT22+AU22+AV22+AW22+AX22+AY22+AZ22+BA22+BB22+BC22+BD22+BE22+BG22+BH22+BK22 -> 235386.45 | BP22: =BL22-BM22 -> 344675.66 | BQ22: =BL22*12 -> 6960745.4 | BR22: =200000+(0.2*BQ22) -> 1592149.1 | BS22: =BI22*12 -> 0 | BT22: =SUM(BR22:BS22) -> 1592149.1 | BU22: =+BQ22-BT22 -> 5368596.3 | BW22: =IF((BU22>0),(IF((BU22>300000),(300000*7%),(BU22*7%))),(BQ22*1%)) -> 21000 | BX22: =IF((BU22-300000)>0,(IF((BU22>600000),(300000*11%),((BU22-300000)*11%))),("")) -> 33000 | BY22: =IF(((BU22-600000)>0),(IF((BU22>1100000),(500000*15%),((BU22-600000)*15%))),("")) -> 75000 | BZ22: =IF(((BU22-(1100000))>0),(IF((BU22>(1600000)),((500000)*19%),((BU22-(1100000))*19%))),("")) -> 95000 | CA22: =IF(((BU22-(1600000))>0),(IF((BU22>(3200000)),((1600000)*21%),((BU22-(1600000))*21%))),("")) -> 336000 | CB22: =IF(((BU22-(3200000))>0),(IF((BU22>(3200000)),((BU22-(3200000))*24%),(0))),("")) -> 520463.11 | CC22: =SUM(BW22:CB22) -> 1080463.1 | CD22: =1%*BQ22 -> 69607.454 | CE22: =MAX(CC22:CD22) -> 1080463.1 | CF22: =+CE22/12 -> 90038.592
A23: 20 | B23: EKOKEME TAMARAUKRO TIMIPRE | C23: BANKING AND FINANCE | D23: SENIOR LECTURER | E23: CONUASS 5/2 | F23: GTB | G23: 0036064176 | H23: 2035373 | I23: 2144788 | J23: =J26 -> 202110.17 | K23: =K26 -> 50527.542 | L23: 30000 | M23: 400171.75 | N23: =M23*0.35/3 -> 46686.704 | O23: 5000 | R23: 2500 | Z23: 2500 | AM23: =M23*0.02 -> 8003.435 | AN23: 500 | AW23: 1000 | BA23: 0 | BE23: 1500 | BH23: =BL23*0.02 -> 9137.1691 | BK23: 66383.49 | BL23: =M23+N23+O23+P23+R23+S23+T23+U23+V23+W23+Y23+Z23+AA23 -> 456858.45 | BM23: =AI23+AJ23+AK23+AL23+AM23+AN23+AP23++AQ23+AR23+AS23+AT23+AU23+AV23+AW23+AX23+AY23+AZ23+BA23+BB23+BC23+BD23+BE23+BG23+BH23+BK23 -> 86524.094 | BP23: =BL23-BM23 -> 370334.36 | BQ23: =BL23*12 -> 5482301.5 | BR23: =200000+(0.2*BQ23) -> 1296460.3 | BS23: =BI23*12 -> 0 | BT23: =SUM(BR23:BS23) -> 1296460.3 | BU23: =+BQ23-BT23 -> 4185841.2 | BW23: =IF((BU23>0),(IF((BU23>300000),(300000*7%),(BU23*7%))),(BQ23*1%)) -> 21000 | BX23: =IF((BU23-300000)>0,(IF((BU23>600000),(300000*11%),((BU23-300000)*11%))),("")) -> 33000 | BY23: =IF(((BU23-600000)>0),(IF((BU23>1100000),(500000*15%),((BU23-600000)*15%))),("")) -> 75000 | BZ23: =IF(((BU23-(1100000))>0),(IF((BU23>(1600000)),((500000)*19%),((BU23-(1100000))*19%))),("")) -> 95000 | CA23: =IF(((BU23-(1600000))>0),(IF((BU23>(3200000)),((1600000)*21%),((BU23-(1600000))*21%))),("")) -> 336000 | CB23: =IF(((BU23-(3200000))>0),(IF((BU23>(3200000)),((BU23-(3200000))*24%),(0))),("")) -> 236601.88 | CC23: =SUM(BW23:CB23) -> 796601.88 | CD23: =1%*BQ23 -> 54823.014 | CE23: =MAX(CC23:CD23) -> 796601.88 | CF23: =+CE23/12 -> 66383.49
A24: 21 | B24: KROKEME OKOYAN | C24: BANKING AND FINANCE | D24: LECTURER I | E24: CONUASS 4/2 | F24: STANBIC IBTC | G24: 0033854745 | H24: 1980666 | I24: 2035373 | J24: 169614.42 | K24: 42403.604 | L24: 30000 | M24: 291760.84 | N24: =M24*0.35/3 -> 34038.764 | O24: 5000 | P24: 20833.33 | R24: 2500 | Z24: 2500 | AM24: =M24*0.02 -> 5835.2167 | AN24: 500 | AP24: 76667 | AW24: 1000 | BA24: 0 | BE24: 1500 | BH24: =BL24*0.02 -> 7132.6586 | BK24: 47140.19 | BL24: =M24+N24+O24+P24+R24+S24+T24+U24+V24+W24+Y24+Z24+AA24 -> 356632.93 | BM24: =AI24+AJ24+AK24+AL24+AM24+AN24+AP24++AQ24+AR24+AS24+AT24+AU24+AV24+AW24+AX24+AY24+AZ24+BA24+BB24+BC24+BD24+BE24+BG24+BH24+BK24 -> 139775.06 | BP24: =BL24-BM24 -> 216857.87 | BQ24: =BL24*12 -> 4279595.2 | BR24: =200000+(0.2*BQ24) -> 1055919 | BS24: =BI24*12 -> 0 | BT24: =SUM(BR24:BS24) -> 1055919 | BU24: =+BQ24-BT24 -> 3223676.1 | BW24: =IF((BU24>0),(IF((BU24>300000),(300000*7%),(BU24*7%))),(BQ24*1%)) -> 21000 | BX24: =IF((BU24-300000)>0,(IF((BU24>600000),(300000*11%),((BU24-300000)*11%))),("")) -> 33000 | BY24: =IF(((BU24-600000)>0),(IF((BU24>1100000),(500000*15%),((BU24-600000)*15%))),("")) -> 75000 | BZ24: =IF(((BU24-(1100000))>0),(IF((BU24>(1600000)),((500000)*19%),((BU24-(1100000))*19%))),("")) -> 95000 | CA24: =IF(((BU24-(1600000))>0),(IF((BU24>(3200000)),((1600000)*21%),((BU24-(1600000))*21%))),("")) -> 336000 | CB24: =IF(((BU24-(3200000))>0),(IF((BU24>(3200000)),((BU24-(3200000))*24%),(0))),("")) -> 5682.275 | CC24: =SUM(BW24:CB24) -> 565682.28 | CD24: =1%*BQ24 -> 42795.952 | CE24: =MAX(CC24:CD24) -> 565682.28 | CF24: =+CE24/12 -> 47140.19
A25: 22 | B25: ADIM CHIDIEBERE VICTOR | C25: BUSINESS ADMINISTRATION | D25: SENIOR LECTURER | E25: CONUASS 5/3 | F25: GTB | G25: 0035615588 | I25: 2090081 | J25: 174173.42 | K25: 43543.354 | L25: 30000 | M25: 413255.25 | N25: =M25*0.35/3 -> 48213.113 | O25: 5000 | P25: 20833.33 | R25: 2500 | Z25: 2500 | AM25: =M25*0.02 -> 8265.105 | AN25: 500 | AW25: 1000 | BA25: 0 | BC25: 3750 | BD25: 7500 | BE25: 1500 | BH25: =BL25*0.02 -> 9846.0338 | BK25: 69188.59 | BL25: =M25+N25+O25+P25+R25+S25+T25+U25+V25+W25+Y25+Z25+AA25 -> 492301.69 | BM25: =AI25+AJ25+AK25+AL25+AM25+AN25+AP25++AQ25+AR25+AS25+AT25+AU25+AV25+AW25+AX25+AY25+AZ25+BA25+BB25+BC25+BD25+BE25+BG25+BH25+BK25 -> 101549.73 | BP25: =BL25-BM25 -> 390751.96 | BQ25: =BL25*12 -> 5907620.3 | BR25: =200000+(0.2*BQ25) -> 1381524.1 | BS25: =BI25*12 -> 0 | BT25: =SUM(BR25:BS25) -> 1381524.1 | BU25: =+BQ25-BT25 -> 4526096.2 | BW25: =IF((BU25>0),(IF((BU25>300000),(300000*7%),(BU25*7%))),(BQ25*1%)) -> 21000 | BX25: =IF((BU25-300000)>0,(IF((BU25>600000),(300000*11%),((BU25-300000)*11%))),("")) -> 33000 | BY25: =IF(((BU25-600000)>0),(IF((BU25>1100000),(500000*15%),((BU25-600000)*15%))),("")) -> 75000 | BZ25: =IF(((BU25-(1100000))>0),(IF((BU25>(1600000)),((500000)*19%),((BU25-(1100000))*19%))),("")) -> 95000 | CA25: =IF(((BU25-(1600000))>0),(IF((BU25>(3200000)),((1600000)*21%),((BU25-(1600000))*21%))),("")) -> 336000 | CB25: =IF(((BU25-(3200000))>0),(IF((BU25>(3200000)),((BU25-(3200000))*24%),(0))),("")) -> 318263.1 | CC25: =SUM(BW25:CB25) -> 878263.1 | CD25: =1%*BQ25 -> 59076.203 | CE25: =MAX(CC25:CD25) -> 878263.1 | CF25: =+CE25/12 -> 73188.592
A26: 23 | B26: LUBO EBISINE | C26: ECONOMICS | D26: LECTURER I | E26: CONUASS 4/2 | F26: STERLING | G26: 0079015111 | H26: 2308911 | I26: 2425322 | J26: 202110.17 | K26: 50527.542 | L26: 30000 | M26: 291760.83 | N26: =M26*0.35/3 -> 34038.764 | O26: 5000 | R26: 2500 | Z26: 2500 | AM26: =M26*0.02 -> 5835.2166 | AN26: 500 | AP26: 93334 | AX26: 1000 | AZ26: 1000 | BA26: 118333.33 | BE26: 1500 | BH26: =BL26*0.02 -> 6715.9919 | BK26: 43581 | BL26: =M26+N26+O26+P26+R26+S26+T26+U26+V26+W26+Y26+Z26+AA26 -> 335799.59 | BM26: =AI26+AJ26+AK26+AL26+AM26+AN26+AP26++AQ26+AR26+AS26+AT26+AU26+AV26+AW26+AX26+AY26+AZ26+BA26+BB26+BC26+BD26+BE26+BG26+BH26+BK26 -> 271799.54 | BP26: =BL26-BM26 -> 64000.055 | BQ26: =BL26*12 -> 4029595.1 | BR26: =200000+(0.2*BQ26) -> 1005919 | BS26: =BI26*12 -> 0 | BT26: =SUM(BR26:BS26) -> 1005919 | BU26: =+BQ26-BT26 -> 3023676.1 | BW26: =IF((BU26>0),(IF((BU26>300000),(300000*7%),(BU26*7%))),(BQ26*1%)) -> 21000 | BX26: =IF((BU26-300000)>0,(IF((BU26>600000),(300000*11%),((BU26-300000)*11%))),("")) -> 33000 | BY26: =IF(((BU26-600000)>0),(IF((BU26>1100000),(500000*15%),((BU26-600000)*15%))),("")) -> 75000 | BZ26: =IF(((BU26-(1100000))>0),(IF((BU26>(1600000)),((500000)*19%),((BU26-(1100000))*19%))),("")) -> 95000 | CA26: =IF(((BU26-(1600000))>0),(IF((BU26>(3200000)),((1600000)*21%),((BU26-(1600000))*21%))),("")) -> 298971.98 | CB26: =IF(((BU26-(3200000))>0),(IF((BU26>(3200000)),((BU26-(3200000))*24%),(0))),("")) | CC26: =SUM(BW26:CB26) -> 522971.98 | CD26: =1%*BQ26 -> 40295.951 | CE26: =MAX(CC26:CD26) -> 522971.98 | CF26: =+CE26/12 -> 43580.998
A27: 24 | B27: OKABA EBIKONBOWEI ALEX | C27: BIOLOGICAL SCIENCE | D27: LECTURER I | E27: CONUASS 4/6 | F27: STERLING | G27: 0059407958 | H27: 2688069 | I27: 2775651 | J27: 231304.25 | K27: 57826.062 | L27: 30000 | M27: 328253.42 | N27: =M27*0.35/3 -> 38296.232 | O27: 5000 | P27: =P22 -> 20833.33 | R27: 2500 | Z27: 2500 | AL27: 93334 | AM27: =M27*0.02 -> 6565.0684 | AN27: 500 | AP27: 109688 | AQ27: 1000 | BA27: 95000 | BE27: 1500 | BH27: =BL27*0.02 -> 7947.6596 | BK27: 54964.2 | BL27: =M27+N27+O27+P27+R27+S27+T27+U27+V27+W27+Y27+Z27+AA27 -> 397382.98 | BM27: =AI27+AJ27+AK27+AL27+AM27+AN27+AP27++AQ27+AR27+AS27+AT27+AU27+AV27+AW27+AX27+AY27+AZ27+BA27+BB27+BC27+BD27+BE27+BG27+BH27+BK27 -> 370498.93 | BP27: =BL27-BM27 -> 26884.054 | BQ27: =BL27*12 -> 4768595.8 | BR27: =200000+(0.2*BQ27) -> 1153719.2 | BS27: =BI27*12 -> 0 | BT27: =SUM(BR27:BS27) -> 1153719.2 | BU27: =+BQ27-BT27 -> 3614876.6 | BW27: =IF((BU27>0),(IF((BU27>300000),(300000*7%),(BU27*7%))),(BQ27*1%)) -> 21000 | BX27: =IF((BU27-300000)>0,(IF((BU27>600000),(300000*11%),((BU27-300000)*11%))),("")) -> 33000 | BY27: =IF(((BU27-600000)>0),(IF((BU27>1100000),(500000*15%),((BU27-600000)*15%))),("")) -> 75000 | BZ27: =IF(((BU27-(1100000))>0),(IF((BU27>(1600000)),((500000)*19%),((BU27-(1100000))*19%))),("")) -> 95000 | CA27: =IF(((BU27-(1600000))>0),(IF((BU27>(3200000)),((1600000)*21%),((BU27-(1600000))*21%))),("")) -> 336000 | CB27: =IF(((BU27-(3200000))>0),(IF((BU27>(3200000)),((BU27-(3200000))*24%),(0))),("")) -> 99570.391 | CC27: =SUM(BW27:CB27) -> 659570.39 | CD27: =1%*BQ27 -> 47685.958 | CE27: =MAX(CC27:CD27) -> 659570.39 | CF27: =+CE27/12 -> 54964.199
A28: 25 | B28: ORIBHABOR BLESSING CHINELO | C28: GUIDANCE AND COUNSELLING | D28: ASSOCIATE PROFESSOR | E28: CONUASS 6/2 | F28: FIRST | G28: 2035909165 | H28: 4432861 | I28: 4558463 | J28: 379871.92 | K28: 94967.979 | L28: 30000 | M28: 480795.42 | N28: =M28*0.35/3 -> 56092.799 | O28: 5000 | R28: 2500 | Z28: 2500 | AM28: =M28*0.02 -> 9615.9084 | AN28: 500 | AP28: 40834 | AS28: 1000 | AY28: 2000 | BA28: 265000 | BC28: 7500 | BD28: 15000 | BE28: 2000 | BH28: =BL28*0.02 -> 10937.764 | BK28: 83669.2 | BL28: =M28+N28+O28+P28+R28+S28+T28+U28+V28+W28+Y28+Z28+AA28 -> 546888.22 | BM28: =AI28+AJ28+AK28+AL28+AM28+AN28+AP28++AQ28+AR28+AS28+AT28+AU28+AV28+AW28+AX28+AY28+AZ28+BA28+BB28+BC28+BD28+BE28+BG28+BH28+BK28 -> 438056.87 | BP28: =BL28-BM28 -> 108831.35 | BQ28: =BL28*12 -> 6562658.6 | BR28: =200000+(0.2*BQ28) -> 1512531.7 | BS28: =BI28*12 -> 0 | BT28: =SUM(BR28:BS28) -> 1512531.7 | BU28: =+BQ28-BT28 -> 5050126.9 | BW28: =IF((BU28>0),(IF((BU28>300000),(300000*7%),(BU28*7%))),(BQ28*1%)) -> 21000 | BX28: =IF((BU28-300000)>0,(IF((BU28>600000),(300000*11%),((BU28-300000)*11%))),("")) -> 33000 | BY28: =IF(((BU28-600000)>0),(IF((BU28>1100000),(500000*15%),((BU28-600000)*15%))),("")) -> 75000 | BZ28: =IF(((BU28-(1100000))>0),(IF((BU28>(1600000)),((500000)*19%),((BU28-(1100000))*19%))),("")) -> 95000 | CA28: =IF(((BU28-(1600000))>0),(IF((BU28>(3200000)),((1600000)*21%),((BU28-(1600000))*21%))),("")) -> 336000 | CB28: =IF(((BU28-(3200000))>0),(IF((BU28>(3200000)),((BU28-(3200000))*24%),(0))),("")) -> 444030.46 | CC28: =SUM(BW28:CB28) -> 1004030.5 | CD28: =1%*BQ28 -> 65626.586 | CE28: =MAX(CC28:CD28) -> 1004030.5 | CF28: =+CE28/12 -> 83669.205
A29: 26 | B29: FRANK SAPELE FUNKEYE | C29: POLITICAL SCIENCE | D29: ASSOCIATE PROFESSOR | E29: CONUASS 6/1 | F29: STERLING | G29: 0073394429 | M29: 464981 | N29: =M29*0.35/3 -> 54247.783 | O29: 5000 | P29: 20833.33 | R29: 2500 | Z29: 2500 | AM29: =M29*0.02 -> 9299.62 | AN29: 500 | AX29: 1000 | AY29: 2000 | BA29: 78833.33 | BC29: 3500 | BD29: 7500 | BE29: 2000 | BH29: 10584.58 | BK29: 84278.53 | BL29: =M29+N29+O29+P29+R29+S29+T29+U29+V29+W29+Y29+Z29+AA29 -> 550062.11 | BM29: =AI29+AJ29+AK29+AL29+AM29+AN29+AP29++AQ29+AR29+AS29+AT29+AU29+AV29+AW29+AX29+AY29+AZ29+BA29+BB29+BC29+BD29+BE29+BG29+BH29+BK29 -> 199496.06 | BP29: =BL29-BM29 -> 350566.05
A30: 27 | B30: BENSON DUNU TONBRAPADE | C30: EDUCATIONAL MANAGEMENT | D30: ASSOCIATE PROFESSOR | E30: CONUAS 6/1 | F30: UNION | G30: 0010851185 | H30: =#REF! -> #REF! | I30: 3804852 | J30: 317071 | K30: 79267.75 | L30: 30000 | M30: 464981 | N30: =M30*0.35/3 -> 54247.783 | O30: 5000 | P30: 41667 | R30: 2500 | Z30: 2500 | AM30: =M30*0.02 -> 9299.62 | AN30: 500 | AP30: 26667 | AS30: 1000 | AV30: 5000 | BA30: 119583.33 | BC30: 7500 | BD30: 15000 | BE30: 2000 | BH30: =BL30*0.02 -> 11417.916 | BK30: 88278.66 | BL30: =Z30+R30+P30+O30+N30+M30 -> 570895.78 | BM30: =AI30+AJ30+AK30+AL30+AM30+AN30+AP30++AQ30+AR30+AS30+AT30+AU30+AV30+AW30+AX30+AY30+AZ30+BA30+BB30+BC30+BD30+BE30+BG30+BH30+BK30 -> 286246.53 | BP30: =BL30-BM30 -> 284649.26 | BQ30: =BL30*12 -> 6850749.4 | BR30: =200000+(0.2*BQ30) -> 1570149.9 | BS30: =BI30*12 -> 0 | BT30: =SUM(BR30:BS30) -> 1570149.9 | BU30: =+BQ30-BT30 -> 5280599.5 | BW30: =IF((BU30>0),(IF((BU30>300000),(300000*7%),(BU30*7%))),(BQ30*1%)) -> 21000 | BX30: =IF((BU30-300000)>0,(IF((BU30>600000),(300000*11%),((BU30-300000)*11%))),("")) -> 33000 | BY30: =IF(((BU30-600000)>0),(IF((BU30>1100000),(500000*15%),((BU30-600000)*15%))),("")) -> 75000 | BZ30: =IF(((BU30-(1100000))>0),(IF((BU30>(1600000)),((500000)*19%),((BU30-(1100000))*19%))),("")) -> 95000 | CA30: =IF(((BU30-(1600000))>0),(IF((BU30>(3200000)),((1600000)*21%),((BU30-(1600000))*21%))),("")) -> 336000 | CB30: =IF(((BU30-(3200000))>0),(IF((BU30>(3200000)),((BU30-(3200000))*24%),(0))),("")) -> 499343.88 | CC30: =SUM(BW30:CB30) -> 1059343.9 | CD30: =1%*BQ30 -> 68507.494 | CE30: =MAX(CC30:CD30) -> 1059343.9 | CF30: =+CE30/12 -> 88278.657
A31: 28 | B31: IYE RONAMI SAMUEL | C31: LIBRARY | D31: ASSISTANT LECTURER | E31: CONUAS 2/4 | F31: ZENITH | G31: 2007556061 | H31: 1691938 | I31: 1796468 | J31: 149705.67 | K31: 37426.417 | L31: 30000 | M31: 222376.83 | N31: =M31*0.35/3 -> 25943.964 | O31: 5000 | R31: 2500 | Z31: 2500 | AM31: =M31*0.02 -> 4447.5366 | AN31: 500 | BA31: 0 | BC31: 7500 | BD31: 15000 | BE31: 1000 | BF31: 1000 | BH31: =BL31*0.02 -> 5166.4159 | BK31: 30564.56 | BL31: =M31+N31+O31+P31+R31+S31+T31+U31+V31+W31+Y31+Z31+AA31 -> 258320.79 | BM31: 65178.51 | BP31: =BL31-BM31 -> 193142.28 | BQ31: =BL31*12 -> 3099849.5 | BR31: =200000+(0.2*BQ31) -> 819969.9 | BS31: =BI31*12 -> 0 | BT31: =SUM(BR31:BS31) -> 819969.9 | BU31: =+BQ31-BT31 -> 2279879.6 | BW31: =IF((BU31>0),(IF((BU31>300000),(300000*7%),(BU31*7%))),(BQ31*1%)) -> 21000 | BX31: =IF((BU31-300000)>0,(IF((BU31>600000),(300000*11%),((BU31-300000)*11%))),("")) -> 33000 | BY31: =IF(((BU31-600000)>0),(IF((BU31>1100000),(500000*15%),((BU31-600000)*15%))),("")) -> 75000 | BZ31: =IF(((BU31-(1100000))>0),(IF((BU31>(1600000)),((500000)*19%),((BU31-(1100000))*19%))),("")) -> 95000 | CA31: =IF(((BU31-(1600000))>0),(IF((BU31>(3200000)),((1600000)*21%),((BU31-(1600000))*21%))),("")) -> 142774.72 | CB31: =IF(((BU31-(3200000))>0),(IF((BU31>(3200000)),((BU31-(3200000))*24%),(0))),("")) | CC31: =SUM(BW31:CB31) -> 366774.72 | CD31: =1%*BQ31 -> 30998.495 | CE31: =MAX(CC31:CD31) -> 366774.72 | CF31: =+CE31/12 -> 30564.56
A32: 29 | B32: ANDERSON BLESSING PERE-ERE | C32: ENGLISH AND LITERARY STUDIES | D32: GRADUATE ASSISTANT | E32: CONUAS 1/3 | F32: STERLING | G32: 0071139983 | J32: 63367 | K32: 15841.75 | L32: 30000 | M32: 192875.25 | N32: =M32*0.35/3 -> 22502.112 | O32: 5000 | R32: 2500 | Z32: 2500 | AM32: =M32*0.02 -> 3857.505 | AN32: 500 | AY32: 2000 | BA32: 0 | BE32: 1000 | BH32: 2580.0986 | BK32: 25030.06 | BL32: =M32+N32+O32+P32+R32+S32+T32+U32+V32+W32+Y32+Z32+AA32 -> 225377.36 | BM32: =AI32+AJ32+AK32+AL32+AM32+AN32+AP32++AQ32+AR32+AS32+AT32+AU32+AV32+AW32+AX32+AY32+AZ32+BA32+BB32+BC32+BD32+BE32+BG32+BH32+BK32 -> 34967.664 | BP32: =BL32-BM32 -> 190409.7 | BQ32: =BL32*12 -> 2704528.4 | BR32: =200000+(0.2*BQ32) -> 740905.67 | BS32: =BI32*12 -> 0 | BT32: =SUM(BR32:BS32) -> 740905.67 | BU32: =+BQ32-BT32 -> 1963622.7 | BW32: =IF((BU32>0),(IF((BU32>300000),(300000*7%),(BU32*7%))),(BQ32*1%)) -> 21000 | BX32: =IF((BU32-300000)>0,(IF((BU32>600000),(300000*11%),((BU32-300000)*11%))),("")) -> 33000 | BY32: =IF(((BU32-600000)>0),(IF((BU32>1100000),(500000*15%),((BU32-600000)*15%))),("")) -> 75000 | BZ32: =IF(((BU32-(1100000))>0),(IF((BU32>(1600000)),((500000)*19%),((BU32-(1100000))*19%))),("")) -> 95000 | CA32: =IF(((BU32-(1600000))>0),(IF((BU32>(3200000)),((1600000)*21%),((BU32-(1600000))*21%))),("")) -> 76360.763 | CB32: =IF(((BU32-(3200000))>0),(IF((BU32>(3200000)),((BU32-(3200000))*24%),(0))),("")) | CC32: =SUM(BW32:CB32) -> 300360.76 | CD32: =1%*BQ32 -> 27045.284 | CE32: =MAX(CC32:CD32) -> 300360.76 | CF32: =+CE32/12 -> 25030.064
A33: 30 | B33: EREBI BOMIEGHA CLEMENT | C33: ENGLISH AND LITERARY STUDIES | D33: GRADUATE ASSISTANT | E33: CONUAS 1/3 | F33: UBA | G33: 2104479346 | J33: 63367 | K33: 15841.75 | L33: 30000 | M33: 192875.25 | N33: =M33*0.35/3 -> 22502.112 | O33: 5000 | R33: 2500 | Z33: 2500 | AM33: =M33*0.02 -> 3857.505 | AN33: 500 | BA33: 0 | BE33: 1000 | BH33: 2580.0986 | BK33: 25030.06 | BL33: =M33+N33+O33+P33+R33+S33+T33+U33+V33+W33+Y33+Z33+AA33 -> 225377.36 | BM33: =AI33+AJ33+AK33+AL33+AM33+AN33+AP33++AQ33+AR33+AS33+AT33+AU33+AV33+AW33+AX33+AY33+AZ33+BA33+BB33+BC33+BD33+BE33+BG33+BH33+BK33 -> 32967.664 | BP33: =BL33-BM33 -> 192409.7 | CF33: =CF32 -> 25030.064
A34: 31 | B34: BRISIBE FRED EMI | C34: THEATRE ARTS | D34: LECTURER II | E34: CONUAS 3/4 | F34: ZENITH | G34: 1002357668 | H34: 1691939 | I34: 2035373 | J34: 169614.42 | K34: 42403.604 | L34: 30000 | M34: 247716.75 | N34: =M34*0.35/3 -> 28900.287 | O34: 5000 | R34: 2500 | Z34: 2500 | AI34: 50000 | AM34: =M34*0.02 -> 4954.335 | AN34: 500 | AP34: 61667 | AS34: 1000 | BA34: 0 | BE34: 1000 | BH34: =BL34*0.02 -> 5732.3408 | BK34: 35318.33 | BL34: =M34+N34+O34+P34+R34+S34+T34+U34+V34+W34+Y34+Z34+AA34 -> 286617.04 | BM34: =AI34+AJ34+AK34+AL34+AM34+AN34+AP34++AQ34+AR34+AS34+AT34+AU34+AV34+AW34+AX34+AY34+AZ34+BA34+BB34+BC34+BD34+BE34+BG34+BH34+BK34 -> 160172.01 | BP34: =BL34-BM34 -> 126445.03 | BQ34: =BL34*12 -> 3439404.5 | BR34: =200000+(0.2*BQ34) -> 887880.89 | BS34: =BI34*12 -> 0 | BT34: =SUM(BR34:BS34) -> 887880.89 | BU34: =+BQ34-BT34 -> 2551523.6 | BW34: =IF((BU34>0),(IF((BU34>300000),(300000*7%),(BU34*7%))),(BQ34*1%)) -> 21000 | BX34: =IF((BU34-300000)>0,(IF((BU34>600000),(300000*11%),((BU34-300000)*11%))),("")) -> 33000 | BY34: =IF(((BU34-600000)>0),(IF((BU34>1100000),(500000*15%),((BU34-600000)*15%))),("")) -> 75000 | BZ34: =IF(((BU34-(1100000))>0),(IF((BU34>(1600000)),((500000)*19%),((BU34-(1100000))*19%))),("")) -> 95000 | CA34: =IF(((BU34-(1600000))>0),(IF((BU34>(3200000)),((1600000)*21%),((BU34-(1600000))*21%))),("")) -> 199819.95 | CB34: =IF(((BU34-(3200000))>0),(IF((BU34>(3200000)),((BU34-(3200000))*24%),(0))),("")) | CC34: =SUM(BW34:CB34) -> 423819.95 | CD34: =1%*BQ34 -> 34394.045 | CE34: =MAX(CC34:CD34) -> 423819.95 | CF34: =+CE34/12 -> 35318.329
A35: 32 | B35: DISEYE ISOWO | C35: COMPUTER SCIENCE AND MATHEMATICAL | D35: LECTURER II | E35: CONUAS 3/3 | F35: GLOBUS | G35: 2003332007 | I35: 1925958 | J35: 160496.5 | K35: 40124.125 | L35: 30000 | M35: 242018.08 | N35: =M35*0.35/3 -> 28235.443 | O35: 5000 | R35: 2500 | Z35: 2500 | AM35: =M35*0.02 -> 4840.3616 | AN35: 500 | AQ35: 1000 | AV35: 10000 | BA35: 0 | BE35: 1000 | BH35: =BL35*0.02 -> 5605.0705 | BK35: 34249.26 | BL35: =M35+N35+O35+P35+R35+S35+T35+U35+V35+W35+Y35+Z35+AA35 -> 280253.52 | BM35: =AI35+AJ35+AK35+AL35+AM35+AN35+AP35++AQ35+AR35+AS35+AT35+AU35+AV35+AW35+AX35+AY35+AZ35+BA35+BB35+BC35+BD35+BE35+BG35+BH35+BK35 -> 57194.692 | BP35: =BL35-BM35 -> 223058.83 | BQ35: =BL35*12 -> 3363042.3 | BR35: =200000+(0.2*BQ35) -> 872608.45 | BS35: =BI35*12 -> 0 | BT35: =SUM(BR35:BS35) -> 872608.45 | BU35: =+BQ35-BT35 -> 2490433.8 | BW35: =IF((BU35>0),(IF((BU35>300000),(300000*7%),(BU35*7%))),(BQ35*1%)) -> 21000 | BX35: =IF((BU35-300000)>0,(IF((BU35>600000),(300000*11%),((BU35-300000)*11%))),("")) -> 33000 | BY35: =IF(((BU35-600000)>0),(IF((BU35>1100000),(500000*15%),((BU35-600000)*15%))),("")) -> 75000 | BZ35: =IF(((BU35-(1100000))>0),(IF((BU35>(1600000)),((500000)*19%),((BU35-(1100000))*19%))),("")) -> 95000 | CA35: =IF(((BU35-(1600000))>0),(IF((BU35>(3200000)),((1600000)*21%),((BU35-(1600000))*21%))),("")) -> 186991.1 | CB35: =IF(((BU35-(3200000))>0),(IF((BU35>(3200000)),((BU35-(3200000))*24%),(0))),("")) | CC35: =SUM(BW35:CB35) -> 410991.1 | CD35: =1%*BQ35 -> 33630.423 | CE35: =MAX(CC35:CD35) -> 410991.1 | CF35: =+CE35/12 -> 34249.258
A36: 33 | B36: OGUNBODEDE FRANCIS KOLAWOLE | C36: LIBRARY | D36: LECTURER II | E36: CONUAS 3/1 | F36: STERLING | G36: 0081963426 | H36: 1796468 | I36: 1846818 | J36: 153901.5 | K36: 38475.375 | L36: 30000 | BQ36: =BL36*12 -> 0 | BR36: =200000+(0.2*BQ36) -> 200000 | BS36: =BI36*12 -> 0 | BT36: =SUM(BR36:BS36) -> 200000 | BU36: =+BQ36-BT36 -> -200000 | BW36: =IF((BU36>0),(IF((BU36>300000),(300000*7%),(BU36*7%))),(BQ36*1%)) -> 0 | BX36: =IF((BU36-300000)>0,(IF((BU36>600000),(300000*11%),((BU36-300000)*11%))),("")) | BY36: =IF(((BU36-600000)>0),(IF((BU36>1100000),(500000*15%),((BU36-600000)*15%))),("")) | BZ36: =IF(((BU36-(1100000))>0),(IF((BU36>(1600000)),((500000)*19%),((BU36-(1100000))*19%))),("")) | CA36: =IF(((BU36-(1600000))>0),(IF((BU36>(3200000)),((1600000)*21%),((BU36-(1600000))*21%))),("")) | CB36: =IF(((BU36-(3200000))>0),(IF((BU36>(3200000)),((BU36-(3200000))*24%),(0))),("")) | CC36: =SUM(BW36:CB36) -> 0 | CD36: =1%*BQ36 -> 0 | CE36: =MAX(CC36:CD36) -> 0 | CF36: =+CE36/12 -> 0
A37: 34 | B37: KPODOH DANIEL OYINMIEBI | C37: THEATRE ARTS | D37: ASSIST LECTURER | E37: CONUAS 2/4 | F37: UBA | G37: 1018108205 | H37: 1796468 | I37: 1796468 | J37: 149705.67 | K37: 37426.417 | L37: 30000 | M37: 222376.83 | N37: =M37*0.35/3 -> 25943.964 | O37: 5000 | R37: 2500 | Z37: 2500 | AM37: =M37*0.02 -> 4447.5366 | AN37: 500 | AS37: 1000 | BA37: 0 | BC37: 4166.67 | BD37: 8333.33 | BE37: 1000 | BH37: =BL37*0.02 -> 5166.4159 | BK37: 30564.56 | BL37: =M37+N37+O37+P37+R37+S37+T37+U37+V37+W37+Y37+Z37+AA37 -> 258320.79 | BM37: =AI37+AJ37+AK37+AL37+AM37+AN37+AP37++AQ37+AR37+AS37+AT37+AU37+AV37+AW37+AX37+AY37+AZ37+BA37+BB37+BC37+BD37+BE37+BG37+BH37+BK37 -> 55178.512 | BP37: =BL37-BM37 -> 203142.28 | BQ37: =BL37*12 -> 3099849.5 | BR37: =200000+(0.2*BQ37) -> 819969.9 | BS37: =BI37*12 -> 0 | BT37: =SUM(BR37:BS37) -> 819969.9 | BU37: =+BQ37-BT37 -> 2279879.6 | BW37: =IF((BU37>0),(IF((BU37>300000),(300000*7%),(BU37*7%))),(BQ37*1%)) -> 21000 | BX37: =IF((BU37-300000)>0,(IF((BU37>600000),(300000*11%),((BU37-300000)*11%))),("")) -> 33000 | BY37: =IF(((BU37-600000)>0),(IF((BU37>1100000),(500000*15%),((BU37-600000)*15%))),("")) -> 75000 | BZ37: =IF(((BU37-(1100000))>0),(IF((BU37>(1600000)),((500000)*19%),((BU37-(1100000))*19%))),("")) -> 95000 | CA37: =IF(((BU37-(1600000))>0),(IF((BU37>(3200000)),((1600000)*21%),((BU37-(1600000))*21%))),("")) -> 142774.72 | CB37: =IF(((BU37-(3200000))>0),(IF((BU37>(3200000)),((BU37-(3200000))*24%),(0))),("")) | CC37: =SUM(BW37:CB37) -> 366774.72 | CD37: =1%*BQ37 -> 30998.495 | CE37: =MAX(CC37:CD37) -> 366774.72 | CF37: =+CE37/12 -> 30564.56
A38: 35 | B38: RICHARD BRILLIANT | C38: ENGLISH AND LITERARY STUDIES | D38: LECTURER I | E38: CONUAS 4/2 | F38: STERLING | G38: 0028949995 | H38: 1980666 | I38: 2035373 | J38: 169614.42 | K38: 42403.604 | L38: 30000 | M38: 291760.83 | N38: =M38*0.35/3 -> 34038.764 | O38: 5000 | R38: 2500 | Z38: 2500 | AM38: =M38*0.02 -> 5835.2166 | AN38: 500 | AS38: 1000 | BA38: 90000 | BE38: 1000 | BF38: 1000 | BH38: =BL38*0.02 -> 6715.9919 | BK38: 43580.998 | BL38: =M38+N38+O38+P38+R38+S38+T38+U38+V38+W38+Y38+Z38+AA38 -> 335799.59 | BM38: =BK38+BH38+BE38+BA38+AS38+AN38+AM38 -> 148632.21 | BP38: =BL38-BM38 -> 187167.39 | BQ38: =BL38*12 -> 4029595.1 | BR38: =200000+(0.2*BQ38) -> 1005919 | BS38: =BI38*12 -> 0 | BT38: =SUM(BR38:BS38) -> 1005919 | BU38: =+BQ38-BT38 -> 3023676.1 | BW38: =IF((BU38>0),(IF((BU38>300000),(300000*7%),(BU38*7%))),(BQ38*1%)) -> 21000 | BX38: =IF((BU38-300000)>0,(IF((BU38>600000),(300000*11%),((BU38-300000)*11%))),("")) -> 33000 | BY38: =IF(((BU38-600000)>0),(IF((BU38>1100000),(500000*15%),((BU38-600000)*15%))),("")) -> 75000 | BZ38: =IF(((BU38-(1100000))>0),(IF((BU38>(1600000)),((500000)*19%),((BU38-(1100000))*19%))),("")) -> 95000 | CA38: =IF(((BU38-(1600000))>0),(IF((BU38>(3200000)),((1600000)*21%),((BU38-(1600000))*21%))),("")) -> 298971.98 | CB38: =IF(((BU38-(3200000))>0),(IF((BU38>(3200000)),((BU38-(3200000))*24%),(0))),("")) | CC38: =SUM(BW38:CB38) -> 522971.98 | CD38: =1%*BQ38 -> 40295.951 | CE38: =MAX(CC38:CD38) -> 522971.98 | CF38: =+CE38/12 -> 43580.998
A39: 36 | B39: NAPOLEON EBIYEFA | C39: HISTORY AND INTERNATIONAL STUDIES | D39: ASSIST LECTURER | E39: CONUAS 2/4 | F39: UBA | G39: 2108025545 | H39: 1746118 | I39: 1796468 | J39: 149705.67 | K39: 37426.417 | L39: 30000 | M39: 222376.83 | N39: =M39*0.35/3 -> 25943.964 | O39: 5000 | R39: 2500 | Z39: 2500 | AM39: =M39*0.02 -> 4447.5366 | AN39: 500 | BA39: 0 | BE39: 1000 | BH39: =BL39*0.02 -> 5166.4159 | BK39: 30564.56 | BL39: =M39+N39+O39+P39+R39+S39+T39+U39+V39+W39+Y39+Z39+AA39 -> 258320.79 | BM39: =AI39+AJ39+AK39+AL39+AM39+AN39+AP39++AQ39+AR39+AS39+AT39+AU39+AV39+AW39+AX39+AY39+AZ39+BA39+BB39+BC39+BD39+BE39+BG39+BH39+BK39 -> 41678.512 | BP39: =BL39-BM39 -> 216642.28 | BQ39: =BL39*12 -> 3099849.5 | BR39: =200000+(0.2*BQ39) -> 819969.9 | BS39: =BI39*12 -> 0 | BT39: =SUM(BR39:BS39) -> 819969.9 | BU39: =+BQ39-BT39 -> 2279879.6 | BW39: =IF((BU39>0),(IF((BU39>300000),(300000*7%),(BU39*7%))),(BQ39*1%)) -> 21000 | BX39: =IF((BU39-300000)>0,(IF((BU39>600000),(300000*11%),((BU39-300000)*11%))),("")) -> 33000 | BY39: =IF(((BU39-600000)>0),(IF((BU39>1100000),(500000*15%),((BU39-600000)*15%))),("")) -> 75000 | BZ39: =IF(((BU39-(1100000))>0),(IF((BU39>(1600000)),((500000)*19%),((BU39-(1100000))*19%))),("")) -> 95000 | CA39: =IF(((BU39-(1600000))>0),(IF((BU39>(3200000)),((1600000)*21%),((BU39-(1600000))*21%))),("")) -> 142774.72 | CB39: =IF(((BU39-(3200000))>0),(IF((BU39>(3200000)),((BU39-(3200000))*24%),(0))),("")) | CC39: =SUM(BW39:CB39) -> 366774.72 | CD39: =1%*BQ39 -> 30998.495 | CE39: =MAX(CC39:CD39) -> 366774.72 | CF39: =+CE39/12 -> 30564.56
A40: 37 | B40: NWOSU NNBUIHE NANCY | C40: EDUCATIONAL MANAGEMENT | D40: ASSOCIATE PROFESSOR | E40: CONUAS 6/4 | F40: FIRST | G40: 3051864825 | H40: 3930454 | I40: 4175818 | J40: 347984.83 | K40: 86996.208 | L40: 30000 | M40: 512424.25 | N40: =M40*0.35/3 -> 59782.829 | O40: 5000 | P40: 20833.33 | R40: 2500 | Z40: 2500 | AM40: =M40*0.02 -> 10248.485 | AN40: 500 | AP40: 45000 | AS40: 1000 | AY40: 2000 | BA40: 97500 | BC40: 4166.67 | BD40: 8333.33 | BE40: 2000 | BH40: =BL40*0.02 -> 12060.808 | BK40: 94450.43 | BL40: =M40+N40+O40+P40+R40+S40+T40+U40+V40+W40+Y40+Z40+AA40 -> 603040.41 | BM40: =AI40+AJ40+AK40+AL40+AM40+AN40+AP40++AQ40+AR40+AS40+AT40+AU40+AV40+AW40+AX40+AY40+AZ40+BA40+BB40+BC40+BD40+BE40+BG40+BH40+BK40 -> 277259.72 | BP40: =BL40-BM40 -> 325780.69 | BQ40: =BL40*12 -> 7236484.9 | BR40: =200000+(0.2*BQ40) -> 1647297 | BS40: =BI40*12 -> 0 | BT40: =SUM(BR40:BS40) -> 1647297 | BU40: =+BQ40-BT40 -> 5589187.9 | BW40: =IF((BU40>0),(IF((BU40>300000),(300000*7%),(BU40*7%))),(BQ40*1%)) -> 21000 | BX40: =IF((BU40-300000)>0,(IF((BU40>600000),(300000*11%),((BU40-300000)*11%))),("")) -> 33000 | BY40: =IF(((BU40-600000)>0),(IF((BU40>1100000),(500000*15%),((BU40-600000)*15%))),("")) -> 75000 | BZ40: =IF(((BU40-(1100000))>0),(IF((BU40>(1600000)),((500000)*19%),((BU40-(1100000))*19%))),("")) -> 95000 | CA40: =IF(((BU40-(1600000))>0),(IF((BU40>(3200000)),((1600000)*21%),((BU40-(1600000))*21%))),("")) -> 336000 | CB40: =IF(((BU40-(3200000))>0),(IF((BU40>(3200000)),((BU40-(3200000))*24%),(0))),("")) -> 573405.1 | CC40: =SUM(BW40:CB40) -> 1133405.1 | CD40: =1%*BQ40 -> 72364.849 | CE40: =MAX(CC40:CD40) -> 1133405.1 | CF40: =+CE40/12 -> 94450.425
...

Sheet BANK SCH
A1: BANK SCHEDULE FOR THE MONTH OF FEBRUARY, 2026
A2: S/N | B2: NAMES OF STAFF | C2: BANK | D2: ACCOUNT NUMBER | E2: AMOUNT
A3: 1 | B3: ADEMOLA AYODEJI JOLAYEMI | C3: FIRST | D3: 2017212564 | E3: 329935.29
A4: 2 | B4: SIKOKI FRANCIS DAVID | C4: ACCESS | D4: 0055002341 | E4: 610935.88
A5: 3 | B5: ABUMERE OAMEN ERONMOSELE | C5: ECOBANK | D5: 0072045836 | E5: 623018.96
A6: 4 | B6: DONBEBE WANKASI | C6: ACCESS | D6: 0026574605 | E6: 267286.12
A7: 5 | B7: CHINYERE P. ONONUGBO | C7: UBA | D7: 2088596893 | E7: 267286.12
A8: 6 | B8: DANIEL I. OLORUNFEMI | C8: ACCESS | D8: 0030621811 | E8: 313800.61
A9: 7 | B9: OKOROBIA MARK ATEI | C9: UBA | D9: 1006415522 | E9: 321437.38
A10: 8 | B10: EBISEITEI PRECIOUS | C10: STANBIC IBTC | D10: 0035529328 | E10: 409418.89
A11: 9 | B11: ZIAKEDE SOLOMON KOROYE | C11: GTB | D11: 0237212657 | E11: 243218.51
A12: 10 | B12: DEINGIMO KEME | C12: UBA | D12: 2067246166 | E12: 279644.14
A13: 11 | B13: TARIEBIBO ENAI GEDE | C13: STERLING | D13: 0077840928 | E13: 289156.06
A14: 12 | B14: LAWAL BABATUNDE YUSUF | C14: STERLING | D14: 0071870439 | E14: 216399
A15: 13 | B15: NEIN GODKNOWS | C15: UNION | D15: 0029213035 | E15: 459007.74
A16: 14 | B16: ECHETA O SYDNEY | C16: FIRST | D16: 3013002388 | E16: 397502.9
A17: 15 | B17: OGBUTA ANTHONY ANWULI | C17: FIRST | D17: 3041696126 | E17: 283489.39
A18: 16 | B18: WAIDOR KEITH TAMARAEBI | C18: WEMA | D18: 0227351994 | E18: 301680.09
A19: 17 | B19: ODUBO CHARITY TAMARAUEBI | C19: STANBIC IBTC | D19: 0019236855 | E19: 257459.55
A20: 18 | B20: OLADIPO ABOSEDE MOJISOLA | C20: ZENITH | D20: 2178561969 | E20: 292489.39
A21: 19 | B21: BOLOUPREMO TARILA | C21: STERLING | D21: 0077210321 | E21: 344675.66
A22: 20 | B22: EKOKEME TAMARAUKRO TIMIPRE | C22: GTB | D22: 0036064176 | E22: 370334.36
A23: 21 | B23: KROKEME OKOYAN | C23: STANBIC IBTC | D23: 0033854745 | E23: 216857.87
A24: 22 | B24: ADIM CHIDIEBERE VICTOR | C24: GTB | D24: 0035615588 | E24: 390751.96
A25: 23 | B25: LUBO EBISINE | C25: STERLING | D25: 0079015111 | E25: 64000.055
A26: 24 | B26: OKABA EBIKONBOWEI ALEX | C26: STERLING | D26: 0059407958 | E26: 26884.054
A27: 25 | B27: ORIBHABOR BLESSING CHINELO | C27: FIRST | D27: 2035909165 | E27: 108831.35
A28: 26 | B28: FRANK SAPELE FUNKEYE | C28: STERLING | D28: 0073394429 | E28: 350566.05
A29: 27 | B29: BENSON DUNU TONBRAPADE | C29: UNION | D29: 0010851185 | E29: 284649.26
A30: 28 | B30: IYE RONAMI SAMUEL | C30: ZENITH | D30: 2007556061 | E30: 193142.28
A31: 29 | B31: ANDERSON BLESSING PERE-ERE | C31: STERLING | D31: 0071139983 | E31: 190409.7
A32: 30 | B32: EREBI BOMIEGHA CLEMENT | C32: UBA | D32: 2104479346 | E32: 192409.7
A33: 31 | B33: BRISIBE FRED EMI | C33: ZENITH | D33: 1002357668 | E33: 126445.03
A34: 32 | B34: DISEYE ISOWO | C34: GLOBUS | D34: 2003332007 | E34: 223058.83
A35: 33 | B35: OGUNBODEDE FRANCIS KOLAWOLE | C35: STERLING | D35: 0081963426
A36: 34 | B36: KPODOH DANIEL OYINMIEBI | C36: UBA | D36: 1018108205 | E36: 203142.28
A37: 35 | B37: RICHARD BRILLIANT | C37: STERLING | D37: 0028949995 | E37: 187167.39
A38: 36 | B38: NAPOLEON EBIYEFA | C38: UBA | D38: 2108025545 | E38: 216642.28
A39: 37 | B39: NWOSU NNBUIHE NANCY | C39: FIRST | D39: 3051864825 | E39: 325780.69
A40: 38 | B40: DONATUS OTAIGBE ONOGBOSELE | C40: ZENITH | D40: 1005415103 | E40: 280650.96
...

Sheet NON TEACHING STAFF
A1: UNIVERSITY OF AFRICA, TORU-ORUA.
A2: NON-TEACHING STAFF SALARY FEBRUARY,2026 | CV2: =CC342 -> 7307490
A3: S/N | B3: NAME OF STAFF | C3: DEPARTMENT | D3: JOB DESCRIPTION | E3: BANK | F3: ACCOUNT NUMBE | G3: GRADE/STEP | H3: scalestep | I3: BANK NAME | J3: ACCT NO | K3: BVN | L3: ANNUAL SALARY | M3: MINIMUM WAGE DIFFERENCE | O3: NEW BASIC | Q3: 25/35% INCREMENT | R3: MINIMUM WAGE | S3: NEW BASIC | T3: SHIFT/CALL DUTY | U3: ARREARS | V3: STIPEND FOR PER TIME TEACHING | W3: FIELD TRIP | X3: EXTRA TEACHING | Y3: PERSONAL OWINGRREARS | Z3: PECULIAR | AA3: EXCESS WORK LOAD | AB3: RESPONSIBILITY | AC3: GENERAL HAZARD | AD3: COMMUNITY RELATION/OTHER ALLOW. | AE3: ='[5] NON-TEACHING STAFF'!$R$2 -> LABOTRATORY HAZARD | AF3: OCCUPATIONAL HARZARD | AG3: DOMESTIC STAFF | AH3: INDUCEMENT | AJ3: MEDICAL ALLOWANCE | AK3: Teaching | AL3: HAZARD | AM3: DOMESTIC STAFF | AN3: Lab wkld | AO3: Rent | AP3: swep | AQ3: Clinical | AR3: NEWSPAPER | AS3: FLORISH WELFARE | AT3: BASIC AND APPLIED SCIENCE WELFARE | AU3: TRANSPORTATION/UTITIY | AV3: SEREBA DIMENSIONAL NIG LTD | AW3: ANUPA | AX3: SSANU | AY3: ECONOMICS DEDUCTION | AZ3: FAE WELFARE DEDUCTION | BA3: SCHOOL FEES GURANTEES | BB3: SALARY ADVANCE | BC3: FSMS WELFARE | BD3: FSS WELFARE | BE3: NASU | BF3: NASU welfare | BG3: FASTGROW | BH3: BURSARY WELFARE | BI3: NAAT DEDUCTION | BJ3: NAAT WELFARE | BK3: ASUU | BL3: UAT RENT | BM3: TOP LIFTERS LIMITED | BN3: BSMICROFINANCE | BO3: UAT CORPORATIVE DEDUCTIONS | BP3: UTILITY | BQ3: DEPENT | BR3: BSETF | BS3: FLORSHINE GLOBAL LIMITED | BT3: BELKARI LOANS | BU3: REFUNDS TO UAT | BV3: EXTRA DEPEND BHIS | BW3: ASUU WELFARE | BX3: UAT CRESTED POLO | BY3: UAT FEMALE FORUM | BZ3: BSETF | CA3: BHIS | CB3: NHF | CC3: P.A.Y.E. | CD3: GROSS PAY | CE3: TOTAL DEDUCTIONS | CF3: NET PAY | CG3: NET PAY | CH3: Gosss Earnings | CI3: Personal Allowance | CJ3: NHF | CK3: Total Non-Taxable Income | CL3: Total Taxable Income | CM3: Minimum tax | CN3: 1st 300K @ 7% | CO3: next 300k @ 11% | CP3: next 500k @ 15% | CQ3: next 500k @ 19% | CR3: next 1.6m @ 21% | CS3: above 3.2m @ 24% | CT3: Min Tax | CU3: Total PAYE Tax | CV3: Monthly PAYE Tax | CW3: 20% Rebate | CX3: ETR | CY3: Current deductions | CZ3: Underpayment (monthly) | DA3: Underpayment (annual) | DB3: REMARK
A4: 327 | B4: MANDA EBIMOBOERE ALICE | C4: LAB TECHNOLOGIST | D4: LABORATORY SENIOR TECHNOLOGIST | E4: GTB | F4: 0112610086 | G4: CONTISS 9/8 | I4: GTB | J4: 0112610086 | K4: 22183492504 | L4: 1967327 | M4: #REF! | N4: 2022036 | O4: 168503 | Q4: 42125.75 | R4: 30000 | S4: 246327.33 | AB4: 25000 | AC4: 2500 | AE4: 30000 | AJ4: 2500 | AL4: 383.33 | AT4: 1000 | AU4: =S4*0.04 -> 9853.0932 | BI4: =S4*0.04 -> 9853.0932 | BL4: 10000 | BO4: 0 | BY4: 2000 | BZ4: 1500 | CA4: 5520.2416 | CC4: 38629.66 | CD4: =AR4+AJ4+AH4+AG4+AE4+AF4+AD4+AC4+AB4+AA4+Z4+Y4+X4+W4+V4+U4+U4+T4+S4 -> 306327.33 | CE4: 78356.09 | CF4: =CD4-CE4 -> 227971.24 | CG4: =CD4-CF4 -> 78356.09
